 <robot name="PiPlusPro_S_12L10A2G2H1W_ZedMini_260322">
  <mujoco>
    <compiler meshdir="../meshes/" balanceinertia="true" discardvisual="false" inertiafromgeom="false" fusestatic="false" />
  </mujoco>

   <link name="base_link">
     <inertial>
       <origin xyz="-0.00028949 4.698e-05 -0.03923366" rpy="0 0 0" />
       <mass value="0.86891839" />
       <inertia ixx="0.00111876" ixy="-2.02e-06" ixz="7.71e-06" iyy="0.00057969" iyz="-1.59e-06" izz="0.00098679" />
     </inertial>
     <visual>
       <origin xyz="0 0 0" rpy="0 0 0" />
       <geometry>
         <mesh filename="package://PiPlusPro_S_12L10A2G2H1W_ZedMini_260322/meshes/base_link.STL" />
       </geometry>
       <material name="">
         <color rgba="0.752941176470588 0.752941176470588 0.752941176470588 1" />
       </material>
     </visual>
     <collision>
       <origin xyz="0 0 -0.045" rpy="0 0 0"/>
       <geometry>
         <box size="0.05 0.07 0.05"/>
       </geometry>
     </collision> 
   </link>
   <link name="r_hip_pitch_link">
     <inertial>
       <origin xyz="7.92e-05 -0.03190261 9.097e-05" rpy="0 0 0" />
       <mass value="0.45931392" />
       <inertia ixx="0.00027163" ixy="1.14e-06" ixz="-6.6e-07" iyy="0.00026494" iyz="-4.1e-07" izz="0.00027956" />
     </inertial>
     <visual>
       <origin xyz="0 0 0" rpy="0 0 0" />
       <geometry>
         <mesh filename="package://PiPlusPro_S_12L10A2G2H1W_ZedMini_260322/meshes/r_hip_pitch_link.STL" />
       </geometry>
       <material name="">
         <color rgba="0.752941176470588 0.752941176470588 0.752941176470588 1" />
       </material>
     </visual>
   </link>
   <joint name="r_hip_pitch_joint" type="revolute">
     <origin xyz="0 -0.0475 -0.0435" rpy="0 0 0" />
     <parent link="base_link" />
     <child link="r_hip_pitch_link" />
     <axis xyz="0 1 0" />
     <limit lower="-3.12" upper="2.94" effort="21" velocity="7.12"/>
     <dynamics damping="0.02" friction="0.0"/> <!-- 即使很小的阻尼也能极大改善稳定性 -->
   </joint>
   <link name="r_hip_roll_link">
     <inertial>
       <origin xyz="0.00102172 -0.00033797 -0.05845832" rpy="0 0 0" />
       <mass value="0.55820116" />
       <inertia ixx="0.00062111" ixy="-1.14e-06" ixz="-3.416e-05" iyy="0.00074025" iyz="-5.5e-07" izz="0.00041298" />
     </inertial>
     <visual>
       <origin xyz="0 0 0" rpy="0 0 0" />
       <geometry>
         <mesh filename="package://PiPlusPro_S_12L10A2G2H1W_ZedMini_260322/meshes/r_hip_roll_link.STL" />
       </geometry>
       <material name="">
         <color rgba="0.752941176470588 0.752941176470588 0.752941176470588 1" />
       </material>
     </visual>
   </link>
   <joint name="r_hip_roll_joint" type="revolute">
     <origin xyz="0 -0.034 0" rpy="0 0 0" />
     <parent link="r_hip_pitch_link" />
     <child link="r_hip_roll_link" />
     <axis xyz="1 0 0" />
     <limit lower="-3.14" upper="0.17" effort="21" velocity="7.12"/>
     <dynamics damping="0.02" friction="0.0"/> <!-- 即使很小的阻尼也能极大改善稳定性 -->
   </joint>
   <link name="r_thigh_link">
     <inertial>
       <origin xyz="0.00064557 -0.00075206 -0.02084055" rpy="0 0 0" />
       <mass value="0.15484273" />
       <inertia ixx="0.00018778" ixy="4.5e-07" ixz="-8.8e-07" iyy="0.00010058" iyz="-5.6e-07" izz="0.00016124" />
     </inertial>
     <visual>
       <origin xyz="0 0 0" rpy="0 0 0" />
       <geometry>
         <mesh filename="package://PiPlusPro_S_12L10A2G2H1W_ZedMini_260322/meshes/r_thigh_link.STL" />
       </geometry>
       <material name="">
         <color rgba="0.752941176470588 0.752941176470588 0.752941176470588 1" />
       </material>
     </visual>
     <collision>
       <origin xyz="0 0 0.065" rpy="0 0 0"/>
       <geometry>
         <cylinder radius="0.035" length="0.055"/>
       </geometry>
     </collision>
   </link>
   <joint name="r_thigh_joint" type="revolute">
     <origin xyz="-0.00035 0 -0.0974" rpy="0 0 0" />
     <parent link="r_hip_roll_link" />
     <child link="r_thigh_link" />
     <axis xyz="0 0 1" />
     <limit lower="-2.87" upper="2.87" effort="21" velocity="7.12"/>
     <dynamics damping="0.02" friction="0.0"/> <!-- 即使很小的阻尼也能极大改善稳定性 -->
   </joint>
   <link name="r_calf_link">
     <inertial>
       <origin xyz="-1.001e-05 -0.00237049 -0.06661243" rpy="0 0 0" />
       <mass value="0.85852308" />
       <inertia ixx="0.00416941" ixy="-6e-08" ixz="-9.9e-06" iyy="0.00414652" iyz="-5.94e-06" izz="0.00042931" />
     </inertial>
     <visual>
       <origin xyz="0 0 0" rpy="0 0 0" />
       <geometry>
         <mesh filename="package://PiPlusPro_S_12L10A2G2H1W_ZedMini_260322/meshes/r_calf_link.STL" />
       </geometry>
       <material name="">
         <color rgba="0.752941176470588 0.752941176470588 0.752941176470588 1" />
       </material>
     </visual>
     <collision>
       <origin xyz="0 0 0" rpy="0 0 0"/>
       <geometry>
         <box size="0.055 0.055 0.055"/>
       </geometry>
     </collision>
     <collision>
       <origin xyz="0 0 -0.065" rpy="0 0 0"/>
       <geometry>
         <box size="0.01 0.02 0.055"/>
       </geometry>
     </collision>
   </link>
   <joint name="r_calf_joint" type="revolute">
     <origin xyz="0 0 -0.045" rpy="0 0 0" />
     <parent link="r_thigh_link" />
     <child link="r_calf_link" />
     <axis xyz="0 1 0" />
     <limit lower="-2.14" upper="2.35" effort="21" velocity="7.12"/>
     <dynamics damping="0.02" friction="0.0"/> <!-- 即使很小的阻尼也能极大改善稳定性 -->
   </joint>
   <link name="r_ankle_pitch_link">
     <inertial>
       <origin xyz="0.00503044 0.00051345 -0.00016685" rpy="0 0 0" />
       <mass value="0.16352634" />
       <inertia ixx="0.00011538" ixy="4.2e-07" ixz="1.65e-06" iyy="0.00020824" iyz="-6.3e-07" izz="0.00028929" />
     </inertial>
     <visual>
       <origin xyz="0 0 0" rpy="0 0 0" />
       <geometry>
         <mesh filename="package://PiPlusPro_S_12L10A2G2H1W_ZedMini_260322/meshes/r_ankle_pitch_link.STL" />
       </geometry>
       <material name="">
         <color rgba="0.752941176470588 0.752941176470588 0.752941176470588 1" />
       </material>
     </visual>
     <collision>
       <origin xyz="0.0035 0 0" rpy="0 0 0"/>
       <geometry>
         <box size="0.07 0.07 0.042"/>
       </geometry>
     </collision>
   </link>
   <joint name="r_ankle_pitch_joint" type="revolute">
     <origin xyz="0 0 -0.14" rpy="0 0 0" />
     <parent link="r_calf_link" />
     <child link="r_ankle_pitch_link" />
     <axis xyz="0 1 0" />
     <limit lower="-0.97" upper="0.92" effort="21" velocity="7.12"/>
     <dynamics damping="0.02" friction="0.0"/> <!-- 即使很小的阻尼也能极大改善稳定性 -->
   </joint>
   <link name="r_ankle_roll_link">
     <inertial>
       <origin xyz="0.0046213 8.211e-05 -0.01502099" rpy="0 0 0" />
       <mass value="0.61662552" />
       <inertia ixx="0.00054662" ixy="-8.4e-07" ixz="-0.00025529" iyy="0.00150792" iyz="8e-07" izz="0.0013343" />
     </inertial>
     <visual>
       <origin xyz="0 0 0" rpy="0 0 0" />
       <geometry>
         <mesh filename="package://PiPlusPro_S_12L10A2G2H1W_ZedMini_260322/meshes/r_ankle_roll_link.STL" />
       </geometry>
       <material name="">
         <color rgba="0.752941176470588 0.752941176470588 0.752941176470588 1" />
       </material>
     </visual>
     <collision>
       <origin xyz="0.028 0 0" rpy="0 0 0"/>
       <geometry>
         <box size="0.06 0.06 0.042"/>
       </geometry>
     </collision>
     <collision>
         <origin xyz="-0.017 -0.025 -0.04" rpy="0 1.5708 0"/>
         <geometry>
             <cylinder radius="0.01" length="0.13"/>
           </geometry>
     </collision>
     <collision>
         <origin xyz="-0.0272 -0.009 -0.04" rpy="0 -1.5708 0"/>
         <geometry>
             <cylinder radius="0.01" length="0.164"/>
           </geometry>
     </collision>
     <collision>
         <origin xyz="-0.0272 0.009 -0.04" rpy="0 -1.5708 0"/>
         <geometry>
             <cylinder radius="0.01" length="0.164"/>
           </geometry>
     </collision>
     <collision>
         <origin xyz="-0.017 0.025 -0.04" rpy="0 1.5708 0"/>
         <geometry>
             <cylinder radius="0.01" length="0.13"/>
           </geometry>
     </collision>
   </link>
   <joint name="r_ankle_roll_joint" type="revolute">
     <origin xyz="0.051 0 0" rpy="0 0 0" />
     <parent link="r_ankle_pitch_link" />
     <child link="r_ankle_roll_link" />
     <axis xyz="1 0 0" />
     <limit lower="-0.78" upper="0.78" effort="21" velocity="7.12"/>
     <dynamics damping="0.02" friction="0.0"/> <!-- 即使很小的阻尼也能极大改善稳定性 -->
   </joint>
   <link name="l_hip_pitch_link">
     <inertial>
       <origin xyz="7.921e-05 0.03190246 -0.0001562" rpy="0 0 0" />
       <mass value="0.45931808" />
       <inertia ixx="0.00027163" ixy="-1.14e-06" ixz="-3.9e-07" iyy="0.00026494" iyz="-2.25e-06" izz="0.00027956" />
     </inertial>
     <visual>
       <origin xyz="0 0 0" rpy="0 0 0" />
       <geometry>
         <mesh filename="package://PiPlusPro_S_12L10A2G2H1W_ZedMini_260322/meshes/l_hip_pitch_link.STL" />
       </geometry>
       <material name="">
         <color rgba="0.752941176470588 0.752941176470588 0.752941176470588 1" />
       </material>
     </visual>
   </link>
   <joint name="l_hip_pitch_joint" type="revolute">
     <origin xyz="0 0.0475 -0.0435" rpy="0 0 0" />
     <parent link="base_link" />
     <child link="l_hip_pitch_link" />
     <axis xyz="0 1 0" />
     <limit lower="-3.12" upper="2.94" effort="21" velocity="7.12"/>
     <dynamics damping="0.02" friction="0.0"/> <!-- 即使很小的阻尼也能极大改善稳定性 -->
   </joint>
   <link name="l_hip_roll_link">
     <inertial>
       <origin xyz="0.00087873 1.341e-05 -0.05845832" rpy="0 0 0" />
       <mass value="0.55820115" />
       <inertia ixx="0.00062117" ixy="-1.07e-06" ixz="-3.583e-05" iyy="0.00074046" iyz="-1.6e-06" izz="0.00041325" />
     </inertial>
     <visual>
       <origin xyz="0 0 0" rpy="0 0 0" />
       <geometry>
         <mesh filename="package://PiPlusPro_S_12L10A2G2H1W_ZedMini_260322/meshes/l_hip_roll_link.STL" />
       </geometry>
       <material name="">
         <color rgba="0.752941176470588 0.752941176470588 0.752941176470588 1" />
       </material>
     </visual>
   </link>
   <joint name="l_hip_roll_joint" type="revolute">
     <origin xyz="0 0.034 0" rpy="0 0 0" />
     <parent link="l_hip_pitch_link" />
     <child link="l_hip_roll_link" />
     <axis xyz="1 0 0" />
     <limit lower="-0.17" upper="3.14" effort="21" velocity="7.12"/>
     <dynamics damping="0.02" friction="0.0"/> <!-- 即使很小的阻尼也能极大改善稳定性 -->
   </joint>
   <link name="l_thigh_link">
     <inertial>
       <origin xyz="0.00071587 0.00075215 -0.0208406" rpy="0 0 0" />
       <mass value="0.15484236" />
       <inertia ixx="0.00018778" ixy="-2.2e-07" ixz="-1.13e-06" iyy="0.00010057" iyz="5.6e-07" izz="0.00016122" />
     </inertial>
     <visual>
       <origin xyz="0 0 0" rpy="0 0 0" />
       <geometry>
         <mesh filename="package://PiPlusPro_S_12L10A2G2H1W_ZedMini_260322/meshes/l_thigh_link.STL" />
       </geometry>
       <material name="">
         <color rgba="0.752941176470588 0.752941176470588 0.752941176470588 1" />
       </material>
     </visual>
     <collision>
       <origin xyz="0 0 0.065" rpy="0 0 0"/>
       <geometry>
         <cylinder radius="0.035" length="0.055"/>
       </geometry>
     </collision>
   </link>
   <joint name="l_thigh_joint" type="revolute">
     <origin xyz="-0.00035 0 -0.0974" rpy="0 0 0" />
     <parent link="l_hip_roll_link" />
     <child link="l_thigh_link" />
     <axis xyz="0 0 1" />
     <limit lower="-2.87" upper="2.87" effort="21" velocity="7.12"/>
     <dynamics damping="0.02" friction="0.0"/> <!-- 即使很小的阻尼也能极大改善稳定性 -->
   </joint>
   <link name="l_calf_link">
     <inertial>
       <origin xyz="-1.001e-05 0.00237048 -0.06661245" rpy="0 0 0" />
       <mass value="0.85852288" />
       <inertia ixx="0.00416941" ixy="6e-08" ixz="9.73e-06" iyy="0.00414651" iyz="5.94e-06" izz="0.00042931" />
     </inertial>
     <visual>
       <origin xyz="0 0 0" rpy="0 0 0" />
       <geometry>
         <mesh filename="package://PiPlusPro_S_12L10A2G2H1W_ZedMini_260322/meshes/l_calf_link.STL" />
       </geometry>
       <material name="">
         <color rgba="0.752941176470588 0.752941176470588 0.752941176470588 1" />
       </material>
     </visual>
     <collision>
       <origin xyz="0 0 0" rpy="0 0 0"/>
       <geometry>
         <box size="0.055 0.055 0.055"/>
       </geometry>
     </collision>
     <collision>
       <origin xyz="0 0 -0.065" rpy="0 0 0"/>
       <geometry>
         <box size="0.01 0.02 0.055"/>
       </geometry>
     </collision>
   </link>
   <joint name="l_calf_joint" type="revolute">
     <origin xyz="0 0 -0.045" rpy="0 0 0" />
     <parent link="l_thigh_link" />
     <child link="l_calf_link" />
     <axis xyz="0 1 0" />
     <limit lower="-2.14" upper="2.35" effort="21" velocity="7.12"/>
     <dynamics damping="0.02" friction="0.0"/> <!-- 即使很小的阻尼也能极大改善稳定性 -->
   </joint>
   <link name="l_ankle_pitch_link">
     <inertial>
       <origin xyz="0.00503044 -0.00051345 -0.00016685" rpy="0 0 0" />
       <mass value="0.16352634" />
       <inertia ixx="0.00011538" ixy="-4.2e-07" ixz="1.65e-06" iyy="0.00020824" iyz="6.3e-07" izz="0.00028929" />
     </inertial>
     <visual>
       <origin xyz="0 0 0" rpy="0 0 0" />
       <geometry>
         <mesh filename="package://PiPlusPro_S_12L10A2G2H1W_ZedMini_260322/meshes/l_ankle_pitch_link.STL" />
       </geometry>
       <material name="">
         <color rgba="0.752941176470588 0.752941176470588 0.752941176470588 1" />
       </material>
     </visual>
     <collision>
       <origin xyz="0.0035 0 0" rpy="0 0 0"/>
       <geometry>
         <box size="0.07 0.07 0.042"/>
       </geometry>
     </collision>
   </link>
   <joint name="l_ankle_pitch_joint" type="revolute">
     <origin xyz="0 0 -0.14" rpy="0 0 0" />
     <parent link="l_calf_link" />
     <child link="l_ankle_pitch_link" />
     <axis xyz="0 1 0" />
     <limit lower="-0.92" upper="0.97" effort="21" velocity="7.12"/>
     <dynamics damping="0.02" friction="0.0"/> <!-- 即使很小的阻尼也能极大改善稳定性 -->
   </joint>
   <link name="l_ankle_roll_link">
     <inertial>
       <origin xyz="0.00456214 8.211e-05 -0.01256536" rpy="0 0 0" />
       <mass value="0.61662552" />
       <inertia ixx="0.00054662" ixy="-8.4e-07" ixz="-0.00025529" iyy="0.00150792" iyz="8e-07" izz="0.0013343" />
     </inertial>
     <visual>
       <origin xyz="0 0 0" rpy="0 0 0" />
       <geometry>
         <mesh filename="package://PiPlusPro_S_12L10A2G2H1W_ZedMini_260322/meshes/l_ankle_roll_link.STL" />
       </geometry>
       <material name="">
         <color rgba="0.752941176470588 0.752941176470588 0.752941176470588 1" />
       </material>
     </visual>
     <collision>
       <origin xyz="0.028 0 0" rpy="0 0 0"/>
       <geometry>
         <box size="0.06 0.06 0.042"/>
       </geometry>
     </collision>
     <collision>
         <origin xyz="-0.017 -0.025 -0.04" rpy="0 1.5708 0"/>
         <geometry>
             <cylinder radius="0.01" length="0.13"/>
           </geometry>
     </collision>
     <collision>
         <origin xyz="-0.0272 -0.009 -0.04" rpy="0 -1.5708 0"/>
         <geometry>
             <cylinder radius="0.01" length="0.164"/>
           </geometry>
     </collision>
     <collision>
         <origin xyz="-0.0272 0.009 -0.04" rpy="0 -1.5708 0"/>
         <geometry>
             <cylinder radius="0.01" length="0.164"/>
           </geometry>
     </collision>
     <collision>
         <origin xyz="-0.017 0.025 -0.04" rpy="0 1.5708 0"/>
         <geometry>
             <cylinder radius="0.01" length="0.13"/>
           </geometry>
     </collision>
   </link>
   <joint name="l_ankle_roll_joint" type="revolute">
     <origin xyz="0.051 0 0" rpy="0 0 0" />
     <parent link="l_ankle_pitch_link" />
     <child link="l_ankle_roll_link" />
     <axis xyz="1 0 0" />
     <limit lower="-0.78" upper="0.78" effort="21" velocity="7.12"/>
     <dynamics damping="0.02" friction="0.0"/> <!-- 即使很小的阻尼也能极大改善稳定性 -->
   </joint>
   <link name="waist_yaw_link">
     <inertial>
       <origin xyz="-2.305e-05 -4.487e-05 0.00298453" rpy="0 0 0" />
       <mass value="0.42252357" />
       <inertia ixx="0.00023331" ixy="1.2e-07" ixz="1.03e-06" iyy="0.00023718" iyz="-5.1e-07" izz="0.00020095" />
     </inertial>
     <visual>
       <origin xyz="0 0 0" rpy="0 0 0" />
       <geometry>
         <mesh filename="package://PiPlusPro_S_12L10A2G2H1W_ZedMini_260322/meshes/waist_yaw_link.STL" />
       </geometry>
       <material name="">
         <color rgba="0.752941176470588 0.752941176470588 0.752941176470588 1" />
       </material>
     </visual>
     <collision>
       <origin xyz="0 0 0.008" rpy="0 0 0"/>
       <geometry>
         <box size="0.05 0.05 0.05"/>
       </geometry>
     </collision>
   </link>
   <joint name="waist_yaw_joint" type="revolute">
     <origin xyz="0 0 0.0248" rpy="0 0 0" />
     <parent link="base_link" />
     <child link="waist_yaw_link" />
     <axis xyz="0 0 1" />
     <limit lower="-2.7" upper="2.7" effort="21" velocity="7.12"/>
     <dynamics damping="0.02" friction="0.0"/> <!-- 即使很小的阻尼也能极大改善稳定性 -->
   </joint>
   <link name="torso_link">
     <inertial>
       <origin xyz="0.00153764 -3.179e-05 0.09595541" rpy="0 0 0" />
       <mass value="2.82493792" />
       <inertia ixx="0.01591654" ixy="8.04e-06" ixz="-0.00011212" iyy="0.01340322" iyz="-2.99e-06" izz="0.01407319" />
     </inertial>
     <visual>
       <origin xyz="0 0 0" rpy="0 0 0" />
       <geometry>
         <mesh filename="package://PiPlusPro_S_12L10A2G2H1W_ZedMini_260322/meshes/torso_link.STL" />
       </geometry>
       <material name="">
         <color rgba="0.752941176470588 0.752941176470588 0.752941176470588 1" />
       </material>
     </visual>
     <collision>
       <origin xyz="0 0 0.09" rpy="0 0 0"/>
       <geometry>
         <box size="0.155 0.155 0.155"/>
       </geometry>
     </collision>
   </link>
   <joint name="torso_joint" type="fixed">
     <origin xyz="0 0 0.0325" rpy="0 0 0" />
     <parent link="waist_yaw_link" />
     <child link="torso_link" />
     <axis xyz="0 0 0" />
     <dynamics damping="0.02" friction="0.0"/> <!-- 即使很小的阻尼也能极大改善稳定性 -->
   </joint>
   <link name="r_shoulder_pitch_link">
     <inertial>
       <origin xyz="-0.0023165 -0.01720478 0.00020825" rpy="0 0 0" />
       <mass value="0.13935188" />
       <inertia ixx="7.568e-05" ixy="-3.2e-06" ixz="5e-08" iyy="0.00012196" iyz="-6.5e-07" izz="0.00014519" />
     </inertial>
     <visual>
       <origin xyz="0 0 0" rpy="0 0 0" />
       <geometry>
         <mesh filename="package://PiPlusPro_S_12L10A2G2H1W_ZedMini_260322/meshes/r_shoulder_pitch_link.STL" />
       </geometry>
       <material name="">
         <color rgba="0.752941176470588 0.752941176470588 0.752941176470588 1" />
       </material>
     </visual>
   </link>
   <joint name="r_shoulder_pitch_joint" type="revolute">
     <origin xyz="0 -0.1084 0.117" rpy="0 0 0" />
     <parent link="torso_link" />
     <child link="r_shoulder_pitch_link" />
     <axis xyz="0 1 0" />
     <limit lower="-4.18" upper="1.04" effort="10" velocity="15.91"/>
     <dynamics damping="0.02" friction="0.0"/> <!-- 即使很小的阻尼也能极大改善稳定性 -->
   </joint>
   <link name="r_shoulder_roll_link">
     <inertial>
       <origin xyz="-0.00164862 -0.00020989 -0.02488799" rpy="0 0 0" />
       <mass value="0.55615019" />
       <inertia ixx="0.00051303" ixy="-2e-07" ixz="1.879e-05" iyy="0.00052161" iyz="-2.18e-06" izz="0.0001534" />
     </inertial>
     <visual>
       <origin xyz="0 0 0" rpy="0 0 0" />
       <geometry>
         <mesh filename="package://PiPlusPro_S_12L10A2G2H1W_ZedMini_260322/meshes/r_shoulder_roll_link.STL" />
       </geometry>
       <material name="">
         <color rgba="0.752941176470588 0.752941176470588 0.752941176470588 1" />
       </material>
     </visual>
   </link>
   <joint name="r_shoulder_roll_joint" type="revolute">
     <origin xyz="0 -0.038 0" rpy="0 0 0" />
     <parent link="r_shoulder_pitch_link" />
     <child link="r_shoulder_roll_link" />
     <axis xyz="1 0 0" />
     <limit lower="-3.34" upper="0.13" effort="10" velocity="15.91"/>
     <dynamics damping="0.02" friction="0.0"/> <!-- 即使很小的阻尼也能极大改善稳定性 -->
   </joint>
   <link name="r_upper_arm_link">
     <inertial>
       <origin xyz="3.107e-05 -0.00138646 -0.01213494" rpy="0 0 0" />
       <mass value="0.15318326" />
       <inertia ixx="0.00017707" ixy="-2.7e-07" ixz="1.4e-07" iyy="0.00011359" iyz="-7.27e-06" izz="0.00014214" />
     </inertial>
     <visual>
       <origin xyz="0 0 0" rpy="0 0 0" />
       <geometry>
         <mesh filename="package://PiPlusPro_S_12L10A2G2H1W_ZedMini_260322/meshes/r_upper_arm_link.STL" />
       </geometry>
       <material name="">
         <color rgba="0.752941176470588 0.752941176470588 0.752941176470588 1" />
       </material>
     </visual>
     <collision>
       <origin xyz="0 0 0.025" rpy="0 0 0"/>
       <geometry>
         <cylinder radius="0.035" length="0.095"/>
       </geometry>
     </collision>
   </link>
   <joint name="r_upper_arm_joint" type="revolute">
     <origin xyz="0 0 -0.0724" rpy="0 0 0" />
     <parent link="r_shoulder_roll_link" />
     <child link="r_upper_arm_link" />
     <axis xyz="0 0 1" />
     <limit lower="-2.16" upper="2.16" effort="10" velocity="15.91"/>
     <dynamics damping="0.02" friction="0.0"/> <!-- 即使很小的阻尼也能极大改善稳定性 -->
   </joint>
   <link name="r_elbow_link">
     <inertial>
       <origin xyz="-2.27e-06 -0.00172514 -0.02376109" rpy="0 0 0" />
       <mass value="0.52332948" />
       <inertia ixx="0.00048622" ixy="2.9e-07" ixz="-1.3e-06" iyy="0.00047242" iyz="1.836e-05" izz="0.00012994" />
     </inertial>
     <visual>
       <origin xyz="0 0 0" rpy="0 0 0" />
       <geometry>
         <mesh filename="package://PiPlusPro_S_12L10A2G2H1W_ZedMini_260322/meshes/r_elbow_link.STL" />
       </geometry>
       <material name="">
         <color rgba="0.752941176470588 0.752941176470588 0.752941176470588 1" />
       </material>
     </visual>
     <collision>
       <origin xyz="0 0 -0.045" rpy="0 0 0"/>
       <geometry>
         <box size="0.042 0.042 0.042"/>
       </geometry>
     </collision>
   </link>
   <joint name="r_elbow_joint" type="revolute">
     <origin xyz="0 0 -0.038" rpy="0 0 0" />
     <parent link="r_upper_arm_link" />
     <child link="r_elbow_link" />
     <axis xyz="0 1 0" />
     <limit lower="-2" upper="2" effort="10" velocity="15.91"/>
     <dynamics damping="0.02" friction="0.0"/> <!-- 即使很小的阻尼也能极大改善稳定性 -->
   </joint>
   <link name="r_wrist_link">
     <inertial>
       <origin xyz="0.00072248 -0.00443407 -0.03057982" rpy="0 0 0" />
       <mass value="0.28659379" />
       <inertia ixx="0.00017096" ixy="-9.5e-07" ixz="-1.16e-06" iyy="0.00017421" iyz="-2.303e-05" izz="9.736e-05" />
     </inertial>
     <visual>
       <origin xyz="0 0 0" rpy="0 0 0" />
       <geometry>
         <mesh filename="package://PiPlusPro_S_12L10A2G2H1W_ZedMini_260322/meshes/r_wrist_link.STL" />
       </geometry>
       <material name="">
         <color rgba="0.752941176470588 0.752941176470588 0.752941176470588 1" />
       </material>
     </visual>
     <collision>
       <origin xyz="0 -0.005 -0.02" rpy="0 0 0"/>
       <geometry>
         <box size="0.042 0.044 0.042"/>
       </geometry>
     </collision>
     <collision>
       <origin xyz="0 -0.0225 -0.06" rpy="0 0 0"/>
       <geometry>
         <box size="0.045 0.01 0.036"/>
       </geometry>
     </collision>
     <collision>
       <origin xyz="0 -0.002 -0.083" rpy="0 0 0"/>
       <geometry>
         <box size="0.05 0.015 0.01"/>
       </geometry>
     </collision>
   </link>
   <joint name="r_wrist_joint" type="revolute">
     <origin xyz="0 0 -0.0724" rpy="0 0 0" />
     <parent link="r_elbow_link" />
     <child link="r_wrist_link" />
     <axis xyz="0 0 1" />
     <limit lower="-3.5" upper="2.4" effort="10" velocity="15.91"/>
     <dynamics damping="0.02" friction="0.0"/> <!-- 即使很小的阻尼也能极大改善稳定性 -->
   </joint>
   <link name="r_gripper_link">
     <inertial>
       <origin xyz="0.00079039 0.00846825 -0.01841999" rpy="0 0 0" />
       <mass value="0.08956926" />
       <inertia ixx="4.601e-05" ixy="6e-07" ixz="-1.3e-06" iyy="8.014e-05" iyz="9.01e-06" izz="4.984e-05" />
     </inertial>
     <visual>
       <origin xyz="0 0 0" rpy="0 0 0" />
       <geometry>
         <mesh filename="package://PiPlusPro_S_12L10A2G2H1W_ZedMini_260322/meshes/r_gripper_link.STL" />
       </geometry>
       <material name="">
         <color rgba="0.752941176470588 0.752941176470588 0.752941176470588 1" />
       </material>
     </visual>
     <collision>
       <origin xyz="0 0.0115 -0.045" rpy="0 0 0"/>
       <geometry>
         <box size="0.05 0.01 0.03"/>
       </geometry>
     </collision>
   </link>
   <joint name="r_gripper_joint" type="revolute">
     <origin xyz="0 0 -0.0265" rpy="0 0 0" />
     <parent link="r_wrist_link" />
     <child link="r_gripper_link" />
     <axis xyz="1 0 0" />
     <limit lower="0" upper="1.04" effort="3.6" velocity="30.37"/>
     <dynamics damping="0.02" friction="0.0"/> <!-- 即使很小的阻尼也能极大改善稳定性 -->
   </joint>
   <link name="l_shoulder_pitch_link">
     <inertial>
       <origin xyz="-0.00215543 0.01720478 0.00022511" rpy="0 0 0" />
       <mass value="0.13935188" />
       <inertia ixx="7.568e-05" ixy="3.32e-06" ixz="1e-07" iyy="0.000122" iyz="6.7e-07" izz="0.00014523" />
     </inertial>
     <visual>
       <origin xyz="0 0 0" rpy="0 0 0" />
       <geometry>
         <mesh filename="package://PiPlusPro_S_12L10A2G2H1W_ZedMini_260322/meshes/l_shoulder_pitch_link.STL" />
       </geometry>
       <material name="">
         <color rgba="0.752941176470588 0.752941176470588 0.752941176470588 1" />
       </material>
     </visual>
   </link>
   <joint name="l_shoulder_pitch_joint" type="revolute">
     <origin xyz="0 0.1084 0.11698" rpy="0 0 0" />
     <parent link="torso_link" />
     <child link="l_shoulder_pitch_link" />
     <axis xyz="0 1 0" />
     <limit lower="-4.18" upper="1.04" effort="10" velocity="15.91"/>
     <dynamics damping="0.02" friction="0.0"/> <!-- 即使很小的阻尼也能极大改善稳定性 -->
   </joint>
   <link name="l_shoulder_roll_link">
     <inertial>
       <origin xyz="-0.00140359 0.00022205 -0.02488799" rpy="0 0 0" />
       <mass value="0.55615015" />
       <inertia ixx="0.00051303" ixy="-1.08e-06" ixz="2.293e-05" iyy="0.00052202" iyz="8.2e-07" izz="0.00015381" />
     </inertial>
     <visual>
       <origin xyz="0 0 0" rpy="0 0 0" />
       <geometry>
         <mesh filename="package://PiPlusPro_S_12L10A2G2H1W_ZedMini_260322/meshes/l_shoulder_roll_link.STL" />
       </geometry>
       <material name="">
         <color rgba="0.752941176470588 0.752941176470588 0.752941176470588 1" />
       </material>
     </visual>
   </link>
   <joint name="l_shoulder_roll_joint" type="revolute">
     <origin xyz="0 0.038 0" rpy="0 0 0" />
     <parent link="l_shoulder_pitch_link" />
     <child link="l_shoulder_roll_link" />
     <axis xyz="1 0 0" />
     <limit lower="-0.13" upper="3.34" effort="10" velocity="15.91"/>
     <dynamics damping="0.02" friction="0.0"/> <!-- 即使很小的阻尼也能极大改善稳定性 -->
   </joint>
   <link name="l_upper_arm_link">
     <inertial>
       <origin xyz="-0.00013535 0.00129534 -0.01213424" rpy="0 0 0" />
       <mass value="0.15318327" />
       <inertia ixx="0.00017715" ixy="-1.2e-07" ixz="5e-07" iyy="0.00011361" iyz="7.46e-06" izz="0.00014221" />
     </inertial>
     <visual>
       <origin xyz="0 0 0" rpy="0 0 0" />
       <geometry>
         <mesh filename="package://PiPlusPro_S_12L10A2G2H1W_ZedMini_260322/meshes/l_upper_arm_link.STL" />
       </geometry>
       <material name="">
         <color rgba="0.752941176470588 0.752941176470588 0.752941176470588 1" />
       </material>
     </visual>
     <collision>
       <origin xyz="0 0 0.025" rpy="0 0 0"/>
       <geometry>
         <cylinder radius="0.035" length="0.095"/>
       </geometry>
     </collision>
   </link>
   <joint name="l_upper_arm_joint" type="revolute">
     <origin xyz="0 0 -0.0724" rpy="0 0 0" />
     <parent link="l_shoulder_roll_link" />
     <child link="l_upper_arm_link" />
     <axis xyz="0 0 1" />
     <limit lower="-2.16" upper="2.16" effort="10" velocity="15.91"/>
     <dynamics damping="0.02" friction="0.0"/> <!-- 即使很小的阻尼也能极大改善稳定性 -->
   </joint>
   <link name="l_elbow_link">
     <inertial>
       <origin xyz="-9.021e-05 0.00173522 -0.02370705" rpy="0 0 0" />
       <mass value="0.52452948" />
       <inertia ixx="0.00048732" ixy="-2e-07" ixz="-1e-07" iyy="0.00047267" iyz="-1.922e-05" izz="0.00012986" />
     </inertial>
     <visual>
       <origin xyz="0 0 0" rpy="0 0 0" />
       <geometry>
         <mesh filename="package://PiPlusPro_S_12L10A2G2H1W_ZedMini_260322/meshes/l_elbow_link.STL" />
       </geometry>
       <material name="">
         <color rgba="0.752941176470588 0.752941176470588 0.752941176470588 1" />
       </material>
     </visual>
     <collision>
       <origin xyz="0 0 -0.045" rpy="0 0 0"/>
       <geometry>
         <box size="0.042 0.042 0.042"/>
       </geometry>
     </collision>
   </link>
   <joint name="l_elbow_joint" type="revolute">
     <origin xyz="0 0 -0.038" rpy="0 0 0" />
     <parent link="l_upper_arm_link" />
     <child link="l_elbow_link" />
     <axis xyz="0 1 0" />
     <limit lower="-2" upper="2" effort="10" velocity="15.91"/>
     <dynamics damping="0.02" friction="0.0"/> <!-- 即使很小的阻尼也能极大改善稳定性 -->
   </joint>
   <link name="l_wrist_link">
     <inertial>
       <origin xyz="0.00072248 0.0044805 -0.03057982" rpy="0 0 0" />
       <mass value="0.28659379" />
       <inertia ixx="0.00017084" ixy="8.5e-07" ixz="-1.16e-06" iyy="0.00017421" iyz="2.291e-05" izz="9.724e-05" />
     </inertial>
     <visual>
       <origin xyz="0 0 0" rpy="0 0 0" />
       <geometry>
         <mesh filename="package://PiPlusPro_S_12L10A2G2H1W_ZedMini_260322/meshes/l_wrist_link.STL" />
       </geometry>
       <material name="">
         <color rgba="0.752941176470588 0.752941176470588 0.752941176470588 1" />
       </material>
     </visual>
     <collision>
       <origin xyz="0 0.005 -0.02" rpy="0 0 0"/>
       <geometry>
         <box size="0.042 0.044 0.042"/>
       </geometry>
     </collision>
     <collision>
       <origin xyz="0 0.0225 -0.06" rpy="0 0 0"/>
       <geometry>
         <box size="0.045 0.01 0.036"/>
       </geometry>
     </collision>
     <collision>
       <origin xyz="0 0.002 -0.083" rpy="0 0 0"/>
       <geometry>
         <box size="0.05 0.015 0.01"/>
       </geometry>
     </collision>
   </link>
   <joint name="l_wrist_joint" type="revolute">
     <origin xyz="0 0 -0.0724" rpy="0 0 0" />
     <parent link="l_elbow_link" />
     <child link="l_wrist_link" />
     <axis xyz="0 0 1" />
     <limit lower="-2.8" upper="3.1" effort="10" velocity="15.91"/>
     <dynamics damping="0.02" friction="0.0"/> <!-- 即使很小的阻尼也能极大改善稳定性 -->
   </joint>
   <link name="l_gripper_link">
     <inertial>
       <origin xyz="0.00079038 -0.0084611 -0.01842328" rpy="0 0 0" />
       <mass value="0.08956926" />
       <inertia ixx="4.601e-05" ixy="-6e-07" ixz="-1.3e-06" iyy="8.015e-05" iyz="-9e-06" izz="4.984e-05" />
     </inertial>
     <visual>
       <origin xyz="0 0 0" rpy="0 0 0" />
       <geometry>
         <mesh filename="package://PiPlusPro_S_12L10A2G2H1W_ZedMini_260322/meshes/l_gripper_link.STL" />
       </geometry>
       <material name="">
         <color rgba="0.752941176470588 0.752941176470588 0.752941176470588 1" />
       </material>
     </visual>
     <collision>
       <origin xyz="0 -0.0115 -0.045" rpy="0 0 0"/>
       <geometry>
         <box size="0.05 0.01 0.03"/>
       </geometry>
     </collision>
   </link>
   <joint name="l_gripper_joint" type="revolute">
     <origin xyz="0 0 -0.0265" rpy="0 0 0" />
     <parent link="l_wrist_link" />
     <child link="l_gripper_link" />
     <axis xyz="1 0 0" />
     <limit lower="-1.04" upper="0" effort="3.6" velocity="30.37"/>
     <dynamics damping="0.02" friction="0.0"/> <!-- 即使很小的阻尼也能极大改善稳定性 -->
   </joint>
   <link name="head_yaw_link">
     <inertial>
       <origin xyz="0.00029301 0.00176257 0.02368926" rpy="0 0 0" />
       <mass value="0.21470364" />
       <inertia ixx="5.913e-05" ixy="3e-08" ixz="7e-07" iyy="5.643e-05" iyz="1.11e-06" izz="5.297e-05" />
     </inertial>
     <visual>
       <origin xyz="0 0 0" rpy="0 0 0" />
       <geometry>
         <mesh filename="package://PiPlusPro_S_12L10A2G2H1W_ZedMini_260322/meshes/head_yaw_link.STL" />
       </geometry>
       <material name="">
         <color rgba="0.752941176470588 0.752941176470588 0.752941176470588 1" />
       </material>
     </visual>
     <collision>
       <origin xyz="0 0 0.0195" rpy="0 0 0"/>
       <geometry>
         <box size="0.035 0.04 0.035"/>
       </geometry>
     </collision>
   </link>
   <joint name="head_yaw_joint" type="revolute">
     <origin xyz="0.014 -0.00026667 0.1981" rpy="0 0 0" />
     <parent link="torso_link" />
     <child link="head_yaw_link" />
     <axis xyz="0 0 1" />
     <limit lower="-1.43" upper="1.43" effort="3.6" velocity="30.37"/>
     <dynamics damping="0.02" friction="0.0"/> <!-- 即使很小的阻尼也能极大改善稳定性 -->
   </joint>
   <link name="head_pitch_link">
     <inertial>
       <origin xyz="0.02668712 -0.00163614 0.05572909" rpy="0 0 0" />
       <mass value="0.33483506" />
       <inertia ixx="0.00081427" ixy="4.19e-06" ixz="-3.393e-05" iyy="0.00055509" iyz="-2.41e-06" izz="0.00101544" />
     </inertial>
     <visual>
       <origin xyz="0 0 0" rpy="0 0 0" />
       <geometry>
         <mesh filename="package://PiPlusPro_S_12L10A2G2H1W_ZedMini_260322/meshes/head_pitch_link.STL" />
       </geometry>
       <material name="">
         <color rgba="0.752941176470588 0.752941176470588 0.752941176470588 1" />
       </material>
     </visual>
     <collision>
       <origin xyz="0.016 0 0.06" rpy="0 0 0"/>
       <geometry>
         <box size="0.1 0.11 0.045"/>
       </geometry>
     </collision>
   </link>
   <joint name="head_pitch_joint" type="revolute">
     <origin xyz="0 0 0.0275" rpy="0 0 0" />
     <parent link="head_yaw_link" />
     <child link="head_pitch_link" />
     <axis xyz="0 1 0" />
     <limit lower="-1.76" upper="1.76" effort="3.6" velocity="30.37"/>
     <dynamics damping="0.02" friction="0.0"/> <!-- 即使很小的阻尼也能极大改善稳定性 -->
   </joint>
   <link name="camera_link">
     <inertial>
       <origin xyz="0.00963743 0.00075253 0.00058537" rpy="0 0 0" />
       <mass value="0.0584" />
       <inertia ixx="7.259e-05" ixy="9.8e-07" ixz="0.0" iyy="5.53e-06" iyz="6e-08" izz="7.249e-05" />
     </inertial>
     <visual>
       <origin xyz="0 0 0" rpy="0 0 0" />
       <geometry>
         <mesh filename="package://PiPlusPro_S_12L10A2G2H1W_ZedMini_260322/meshes/camera_link.STL" />
       </geometry>
       <material name="">
         <color rgba="0.752941176470588 0.752941176470588 0.752941176470588 1" />
       </material>
     </visual>
   </link>
   <joint name="camera_joint" type="fixed">
     <origin xyz="0.048925 0.0053519 0.058472" rpy="0 0 0" />
     <parent link="head_pitch_link" />
     <child link="camera_link" />
     <axis xyz="0 0 0" />
     <dynamics damping="0.02" friction="0.0"/> <!-- 即使很小的阻尼也能极大改善稳定性 -->
   </joint>
 </robot>